Workbook

Sheet Yearly
B3: 2026
C4: Forecasted | E4: Actual | G4: Delta forecast | H4: Delta month | I4: Bank
C5: Expenses | D5: Income | E5: Expenses | F5: Income | G5: Net | I5: Forecasted | J5: Actual | K5: Intesa | L5: Revolut | M5: To receive | N5: TOT
B6: 46023 | C6: {='January'!G$41} -> 912.47 | D6: {='January'!K$47} -> 597 | E6: {='January'!H$41} -> 912.47 | F6: {='January'!L$47} -> 627 | G6: {=(F6-E6)-(D6-C6)} -> 30 | H6: {=F6-E6} -> -285.47 | I6: {=6966.21+(D6-C6)} -> 6650.74 | J6: {=6966.21+H6} -> 6680.74
B7: 46054 | C7: {='February'!G$42} -> 138.88 | D7: 8300 | E7: {='February'!H$42} -> 138.88 | F7: {='February'!L$48} -> 8322.9 | G7: {=(F7-E7)-(D7-C7)} -> 22.9 | H7: {=F7-E7} -> 8184.02 | I7: {=I6+(D7-C7)} -> 14811.86 | J7: {=J6+H7} -> 14864.76
B8: 46082 | C8: {='March'!G$54} -> 1690.59 | D8: 4500 | E8: {='March'!H$54} -> 1690.59 | F8: 4573 | G8: {=(F8-E8)-(D8-C8)} -> 73 | H8: {=F8-E8} -> 2882.41 | I8: {=I7+(D8-C8)} -> 17621.27 | J8: {=J7+H8} -> 17747.17
B9: 46113 | C9: {='April'!J$76} -> 2963.7792 | D9: 2108 | E9: {='April'!K$76} -> 2963.9508 | F9: {='April'!O$82} -> 2108.4791 | G9: {=(F9-E9)-(D9-C9)} -> 0.3074831 | H9: {=F9-E9} -> -855.47171 | I9: {=I8+(D9-C9)} -> 16765.491 | J9: {=J8+H9} -> 16891.698
B10: 46143 | C10: {='May'!J$110} -> 2573.48 | D10: 0 | E10: {='May'!K$110} -> 3228.0731 | F10: {='May'!O$116} -> 838 | G10: {=(F10-E10)-(D10-C10)} -> 183.40694 | H10: {=F10-E10} -> -2390.0731 | I10: {=I9+(D10-C10)} -> 14192.011 | J10: {=J9+H10} -> 14501.625 | K10: {=K11+949+2.89+150.5+20.99} -> 9110.07 | L10: {=1500+0.8582*2644.81} -> 3769.7759 | M10: {=188.8+948+469.63} -> 1606.43 | N10: {=SUM(K10:M10)} -> 14486.276 | O10: {=N10-J10} -> -15.349287
B11: 46174 | C11: {='June'!J$90} -> 1873.48 | D11: 0 | E11: {='June'!K$90} -> 2162.0507 | F11: {='June'!O$96} -> 47.408116 | G11: {=(F11-E11)-(D11-C11)} -> -241.16257 | H11: {=F11-E11} -> -2114.6426 | I11: {=I10+(D11-C11)} -> 12318.531 | J11: {=J10+H11} -> 12386.983 | K11: {=7986.69} -> 7986.69 | L11: {=1469.85*0.8582+1483.42} -> 2744.8453 | M11: {=188.8+948+469.63+135.68} -> 1742.11 | N11: {=SUM(K11:M11)} -> 12473.645 | O11: {=N11-J11} -> 86.662609 | P11: Rimborso Michael + rimborso caparra casa+ ceci sf + cena carbonara
B12: 46204 | C12: {='July'!N$109} -> 2069.23 | D12: 0 | E12: {='July'!O$109} -> 2045.1535 | F12: {='July'!S$115} -> 332.9725 | G12: {=(F12-E12)-(D12-C12)} -> 357.04896 | H12: {=F12-E12} -> -1712.181 | I12: {=I11+(D12-C12)} -> 10249.301 | J12: {=J11+H12} -> 10674.802 | K12: {=12216.69-5219} -> 6997.69 | L12: {=657.93*0.8582+1876.67} -> 2441.3055 | M12: {=948+469.63} -> 1417.63 | N12: {=SUM(K12:M12)} -> 10856.626 | O12: {=N12-J12} -> 181.8239
B13: 46235 | C13: {='August'!G$42} -> 1873.48 | D13: 0 | E13: 0 | F13: 0 | G13: {=(F13-E13)-(D13-C13)} -> 1873.48 | H13: {=F13-E13} -> 0 | I13: {=I12+(D13-C13)} -> 8375.8208 | J13: {=J12+H13} -> 10674.802
B14: 46266 | C14: {='Budgeting'!J13} -> 1847.38 | D14: 0 | E14: 0 | F14: 0 | G14: {=(F14-E14)-(D14-C14)} -> 1847.38 | H14: {=F14-E14} -> 0 | I14: {=I13+(D14-C14)} -> 6528.4408 | J14: {=J13+H14} -> 10674.802
B15: 46296 | C15: 0 | D15: 0 | E15: 0 | F15: 0 | G15: {=(F15-E15)-(D15-C15)} -> 0 | H15: {=F15-E15} -> 0 | I15: {=I14+(D15-C15)} -> 6528.4408 | J15: {=J14+H15} -> 10674.802
B16: 46327 | C16: 0 | D16: 0 | E16: 0 | F16: 0 | G16: {=(F16-E16)-(D16-C16)} -> 0 | H16: {=F16-E16} -> 0 | I16: {=I15+(D16-C16)} -> 6528.4408 | J16: {=J15+H16} -> 10674.802
B17: 46357 | C17: 0 | D17: 0 | E17: 0 | F17: 0 | G17: {=(F17-E17)-(D17-C17)} -> 0 | H17: {=F17-E17} -> 0 | I17: {=I16+(D17-C17)} -> 6528.4408 | J17: {=J16+H17} -> 10674.802

Sheet Budgeting
A1: 2026
B2: 46023 | C2: 46054 | D2: 46082 | E2: 46113 | F2: 46143 | G2: 46174 | H2: 46204 | I2: 46235 | J2: 46266 | K2: 46296 | L2: 46327 | M2: 46357
A3: Restaurant | B3: 0 | C3: {=SUMIF('February'!D3:D29,$A3,'February'!E3:E29)} -> 4.3 | D3: 99.64 | E3: 192.43629 | F3: {='Budget USA'!$D$2*SUM('Budget USA'!L6:O6)} -> 139.2 | G3: {='Budget USA'!$D$2*SUM('Budget USA'!P6:S6)} -> 139.2 | H3: {='Budget USA'!$D$2*SUM('Budget USA'!T6:X6)} -> 174 | I3: {='Budget USA'!$D$2*SUM('Budget USA'!Y6:AB6)} -> 139.2 | J3: 139.2
A4: Sport & Activities | B4: 8 | C4: {=SUMIF('February'!D3:D29,$A4,'February'!E3:E29)} -> 46 | D4: 23 | E4: 0 | F4: 100 | G4: 0 | H4: 0 | I4: 0 | J4: 0
A5: Food | B5: 0 | C5: {=SUMIF('February'!D3:D29,$A5,'February'!E3:E29)} -> 4.6 | D5: 91.45 | E5: 208.62335 | F5: {='Budget USA'!$D$2*SUM('Budget USA'!L8:O8)} -> 287.1 | G5: {='Budget USA'!$D$2*SUM('Budget USA'!P8:S8)} -> 287.1 | H5: {='Budget USA'!$D$2*SUM('Budget USA'!T8:X8)} -> 356.7 | I5: {='Budget USA'!$D$2*SUM('Budget USA'!Y8:AB8)} -> 287.1 | J5: 261
A6: Home | B6: 0 | C6: {=SUMIF('February'!D3:D29,$A6,'February'!E3:E29)} -> 36.13 | D6: 0 | E6: 1867.29 | F6: 1600 | G6: 1000 | H6: 1000 | I6: 1000 | J6: 1000
A7: Medical | B7: 20 | C7: {=SUMIF('February'!D3:D29,$A7,'February'!E3:E29)} -> 0 | D7: 568.82 | E7: 0 | F7: 0 | G7: 0 | H7: 0 | I7: 0 | J7: 0
A8: Personal Items | B8: 850 | C8: {=SUMIF('February'!D3:D29,$A8,'February'!E3:E29)} -> 0 | D8: 295.45 | E8: 145.52 | F8: 0 | G8: 0 | H8: 0 | I8: 0 | J8: 0
A9: Travel & auto | B9: 10 | C9: {=SUMIF('February'!D3:D29,$A9,'February'!E3:E29)} -> 10.36 | D9: 14.35 | E9: 70.74 | F9: 278.4 | G9: 278.4 | H9: 348 | I9: 278.4 | J9: 87
A10: Utilities | B10: 30 | C10: 5 | D10: 39.9 | E10: 52.42 | F10: {='Budget USA'!$D$2*(SUM('Budget USA'!L10:O10)+62)} -> 81.78 | G10: {='Budget USA'!$D$2*(SUM('Budget USA'!M10:P10)+62)} -> 81.78 | H10: {='Budget USA'!$D$2*(SUM('Budget USA'!N10:Q10)+62)} -> 81.78 | I10: {='Budget USA'!$D$2*(SUM('Budget USA'!O10:R10)+62)} -> 81.78 | J10: {='Budget USA'!$D$2*(SUM('Budget USA'!P10:S10)+62)} -> 81.78
A11: Other | B11: 30 | C11: {=SUMIF('February'!D3:D29,$A11,'February'!E3:E29)} -> 32.49 | D11: 557.98 | E11: 426.74956 | F11: 87 | G11: 87 | H11: 108.75 | I11: 87 | J11: 278.4
A12: Investment | B12: 0 | C12: 0 | D12: 0 | E12: 0 | F12: 0 | G12: 0 | H12: 0 | I12: 0 | J12: 0
A13: Total | B13: {=SUM(B3:B12)} -> 948 | C13: {=SUM(C3:C12)} -> 138.88 | D13: {=SUM(D3:D12)} -> 1690.59 | E13: {=SUM(E3:E12)} -> 2963.7792 | F13: {=SUM(F3:F12)} -> 2573.48 | G13: {=SUM(G3:G12)} -> 1873.48 | H13: {=SUM(H3:H12)} -> 2069.23 | I13: {=SUM(I3:I12)} -> 1873.48 | ... M13: {=SUM(M3:M12)} -> 0
N15: Subscriptions
N17: Apple Creator Studio | O17: 2.99
N18: Spotify | O18: {=21/6} -> 3.5
N25: Total | O25: {=SUM(O17:O24)} -> 6.49
S27: 2026-1
T28: 46023 | U28: 46054 | V28: 46082 | W28: 46113 | X28: 46143 | Y28: 46174 | Z28: 46204 | AA28: 46235 | AB28: 46266 | AC28: 46296 | AD28: 46327 | AE28: 46357
S29: Restaurant | T29: 0 | U29: {=SUMIF('February'!D3:D29,$S29,'February'!E3:E29)} -> 4.3 | V29: 150 | W29: {='Budget USA'!D2*SUM('Budget USA'!G6:K6)} -> 174 | X29: {='Budget USA'!$D$2*SUM('Budget USA'!L6:O6)} -> 139.2 | Y29: {='Budget USA'!$D$2*SUM('Budget USA'!P6:S6)} -> 139.2 | Z29: {='Budget USA'!$D$2*SUM('Budget USA'!T6:X6)} -> 174 | AA29: {='Budget USA'!$D$2*SUM('Budget USA'!Y6:AB6)} -> 139.2 | AB29: 139.2
S30: Sport & Activities | T30: 8 | U30: {=SUMIF('February'!D3:D29,$S30,'February'!E3:E29)} -> 46 | V30: 50 | W30: {='Budget USA'!D2*SUM('Budget USA'!G7:K7)} -> 87 | X30: {='Budget USA'!$D$2*SUM('Budget USA'!L7:O7)} -> 69.6 | Y30: {='Budget USA'!$D$2*SUM('Budget USA'!P7:S7)} -> 69.6 | Z30: {='Budget USA'!$D$2*SUM('Budget USA'!T7:X7)} -> 87 | AA30: {='Budget USA'!$D$2*SUM('Budget USA'!Y7:AB7)} -> 69.6 | AB30: 69.6
S31: Food | T31: 0 | U31: {=SUMIF('February'!D3:D29,$S31,'February'!E3:E29)} -> 4.6 | V31: 80 | W31: {='Budget USA'!D2*SUM('Budget USA'!G8:K8)} -> 356.7 | X31: {='Budget USA'!$D$2*SUM('Budget USA'!L8:O8)} -> 287.1 | Y31: {='Budget USA'!$D$2*SUM('Budget USA'!P8:S8)} -> 287.1 | Z31: {='Budget USA'!$D$2*SUM('Budget USA'!T8:X8)} -> 356.7 | AA31: {='Budget USA'!$D$2*SUM('Budget USA'!Y8:AB8)} -> 287.1 | AB31: 261
S32: Home | T32: 0 | U32: {=SUMIF('February'!D3:D29,$S32,'February'!E3:E29)} -> 36.13 | V32: 0 | W32: 1800 | X32: 1400 | Y32: 1400 | Z32: 1400 | AA32: 1400 | AB32: 1400
S33: Medical | T33: 20 | U33: {=SUMIF('February'!D3:D29,$S33,'February'!E3:E29)} -> 0 | V33: 600 | W33: 0 | X33: 0 | Y33: 0 | Z33: 0 | AA33: 0 | AB33: 0
S34: Personal Items | T34: 850 | U34: {=SUMIF('February'!D3:D29,$S34,'February'!E3:E29)} -> 0 | V34: 200 | W34: 0 | X34: 0 | Y34: 0 | Z34: 0 | AA34: 0 | AB34: 0
S35: Travel & auto | T35: 10 | U35: {=SUMIF('February'!D3:D29,$S35,'February'!E3:E29)} -> 10.36 | V35: 950 | W35: {='Budget USA'!D2*SUM('Budget USA'!G9:K9)} -> 108.75 | X35: 278.4 | Y35: 278.4 | Z35: {='Budget USA'!$D$2*SUM('Budget USA'!T9:X9)} -> 108.75 | AA35: 278.4 | AB35: 87
S36: Utilities | T36: 30 | U36: 5 | V36: 30 | W36: {='Budget USA'!$D$2*(SUM('Budget USA'!K10:N10)+62)} -> 81.78 | X36: {='Budget USA'!$D$2*(SUM('Budget USA'!L10:O10)+62)} -> 81.78 | Y36: {='Budget USA'!$D$2*(SUM('Budget USA'!M10:P10)+62)} -> 81.78 | Z36: {='Budget USA'!$D$2*(SUM('Budget USA'!N10:Q10)+62)} -> 81.78 | AA36: {='Budget USA'!$D$2*(SUM('Budget USA'!O10:R10)+62)} -> 81.78 | AB36: {='Budget USA'!$D$2*(SUM('Budget USA'!P10:S10)+62)} -> 81.78
S37: Other | T37: 30 | U37: {=SUMIF('February'!D3:D29,$S37,'February'!E3:E29)} -> 32.49 | V37: 500 | W37: {='Budget USA'!D2*SUM('Budget USA'!G11:K11)} -> 348 | X37: 87 | Y37: 87 | Z37: {='Budget USA'!$D$2*SUM('Budget USA'!T11:X11)} -> 348 | AA37: 87 | AB37: 278.4
S38: Investment | T38: 0 | U38: 0 | V38: 0 | W38: 0 | X38: 0 | Y38: 0 | Z38: 0 | AA38: 0 | AB38: 0
S39: Total | T39: {=SUM(T29:T38)} -> 948 | U39: {=SUM(U29:U38)} -> 138.88 | V39: {=SUM(V29:V38)} -> 2560 | W39: {=SUM(W29:W38)} -> 2956.23 | X39: {=SUM(X29:X38)} -> 2343.08 | Y39: {=SUM(Y29:Y38)} -> 2343.08 | Z39: {=SUM(Z29:Z38)} -> 2556.23 | AA39: {=SUM(AA29:AA38)} -> 2343.08 | ... AE39: {=SUM(AE29:AE38)} -> 0
AF41: Valore conversione
AF42: Euro | AG42: Dollari
AF43: 879.64 | AG43: 1023.52 | AH43: {=$AF43/AG43} -> 0.85942629
AF44: 1421.54 | AG44: 1660 | AH44: {=$AF44/AG44} -> 0.8563494
AF45: 1500 | AG45: 1745.62 | AH45: {=$AF45/AG45} -> 0.85929355
AF51: Media pesata | AH51: {=(SUM($AF43:$AF50))/(SUM(AG43:AG50))} -> 0.85822078

Sheet Budget USA
B2: CONVERSIONE VALUTA | C2: USD to EUR | D2: 0.87
C4: Mar | G4: Apr | L4: May | P4: Jun | T4: Jul | Y4: Aug
C5: W1 | D5: W2 | E5: W3 | F5: W4 | G5: W5 | H5: W6 | I5: W7 | J5: W8 | K5: W9 | L5: W10 | M5: W11 | N5: W12 | O5: W13 | P5: W14 | Q5: W15 | R5: W16 | S5: W17 | T5: W18 | U5: W19 | V5: W20 | W5: W21 | X5: W22 | Y5: W23 | Z5: W24 | AA5: W25 | AB5: W26 | AC5: TOTAL | AD5: TOT EUR
B6: Restaurant | G6: 40 | H6: 40 | I6: 40 | J6: 40 | K6: 40 | L6: 40 | M6: 40 | N6: 40 | O6: 40 | P6: 40 | Q6: 40 | R6: 40 | S6: 40 | T6: 40 | U6: 40 | V6: 40 | W6: 40 | X6: 40 | Y6: 40 | Z6: 40 | AA6: 40 | AB6: 40
B7: Sport | D7: 20 | E7: 20 | F7: 20 | G7: 20 | H7: 20 | I7: 20 | J7: 20 | K7: 20 | L7: 20 | M7: 20 | N7: 20 | O7: 20 | P7: 20 | Q7: 20 | R7: 20 | S7: 20 | T7: 20 | U7: 20 | V7: 20 | W7: 20 | X7: 20 | Y7: 20 | Z7: 20 | AA7: 20 | AB7: 20 | AC7: {=SUM(C7:AB7)} -> 500 | AD7: {=$D$2*AC7} -> 435
B8: Grocery | D8: 90 | E8: 70 | F8: 70 | G8: 90 | H8: 80 | I8: 80 | J8: 80 | K8: 80 | L8: 90 | M8: 80 | N8: 80 | O8: 80 | P8: 90 | Q8: 80 | R8: 80 | S8: 80 | T8: 90 | U8: 80 | V8: 80 | W8: 80 | X8: 80 | Y8: 90 | Z8: 80 | AA8: 80 | AB8: 80 | AC8: {=SUM(C8:AB8)} -> 2040 | AD8: {=$D$2*AC8} -> 1774.8
B9: Transport | D9: 25 | E9: 25 | F9: 25 | G9: 25 | H9: 25 | I9: 25 | J9: 25 | K9: 25 | L9: 25 | M9: 25 | N9: 25 | O9: 25 | P9: 25 | Q9: 25 | R9: 25 | S9: 25 | T9: 25 | U9: 25 | V9: 25 | W9: 25 | X9: 25 | Y9: 25 | Z9: 25 | AA9: 25 | AB9: 25 | AC9: {=SUM(C9:AB9)} -> 625 | AD9: {=$D$2*AC9} -> 543.75
B10: Phone | D10: 8 | E10: 8 | F10: 8 | G10: {=F10} -> 8 | H10: {=G10} -> 8 | I10: {=H10} -> 8 | J10: {=I10} -> 8 | K10: {=J10} -> 8 | L10: {=K10} -> 8 | M10: {=L10} -> 8 | N10: {=M10} -> 8 | ... AB10: {=AA10} -> 8 | AC10: {=SUM(C10:AB10)} -> 200 | AD10: {=$D$2*AC10} -> 174
B11: Extra expences | D11: 120 | E11: 120 | F11: 120 | G11: 80 | H11: 80 | I11: 80 | J11: 80 | K11: 80 | L11: 80 | M11: 80 | N11: 80 | O11: 80 | P11: 80 | Q11: 80 | R11: 80 | S11: 80 | T11: 80 | U11: 80 | V11: 80 | W11: 80 | X11: 80 | Y11: 80 | Z11: 80 | AA11: 80 | AB11: 80 | AC11: {=SUM(C11:AB11)} -> 2120 | AD11: {=$D$2*AC11} -> 1844.4
AC12: {=SUM(C12:Y12)} -> 0 | AD12: {=$D$2*AC12} -> 0
B13: TOTAL | C13: {=SUM(C6:C12)} -> 0 | D13: {=SUM(D6:D12)} -> 263 | E13: {=SUM(E6:E12)} -> 243 | F13: {=SUM(F6:F12)} -> 243 | G13: {=SUM(G6:G12)} -> 263 | H13: {=SUM(H6:H12)} -> 253 | I13: {=SUM(I6:I12)} -> 253 | J13: {=SUM(J6:J12)} -> 253 | ... AB13: {=SUM(AB6:AB12)} -> 253 | AC13: {=SUM(C13:AB13)} -> 6365 | AD13: {=$D$2*AC13} -> 5537.55
B14: TOT MOTH | C14: {=SUM(C13:F13)} -> 749 | G14: {=SUM(G13:K13)} -> 1275 | L14: {=SUM(L13:O13)} -> 1022 | P14: {=SUM(P13:S13)} -> 1022 | T14: {=T13+U13+V13+X13+W13} -> 1275 | Y14: {=Y13+Z13+AA13+AB13} -> 1022 | AC14: {=SUM(C14:AB14)} -> 6365 | AD14: {=$D$2*AC14} -> 5537.55
B15: Tot eur | C15: {=$D$2*C13} -> 0 | D15: {=$D$2*D13} -> 228.81 | E15: {=$D$2*E13} -> 211.41 | F15: {=$D$2*F13} -> 211.41 | G15: {=$D$2*G13} -> 228.81 | H15: {=$D$2*H13} -> 220.11 | I15: {=$D$2*I13} -> 220.11 | J15: {=$D$2*J13} -> 220.11 | ... AB15: {=$D$2*AB13} -> 220.11
B17: Cahsflow | C17: {=9000-C15} -> 9000 | D17: {=C17-D15} -> 8771.19 | E17: {=D17-E15} -> 8559.78 | F17: {=E17-F15} -> 8348.37 | G17: {=F17-G15} -> 8119.56 | H17: {=G17-H15} -> 7899.45 | I17: {=H17-I15} -> 7679.34 | J17: {=I17-J15} -> 7459.23 | K17: {=J17-K15} -> 7239.12 | ... AB17: {=AA17-AB15} -> 3462.45 | AC17: Residuo USD | AD17: {=AB17*1/D2} -> 3979.8276
B19: Affitto | C19: 1000 | D19: {=C19*5} -> 5000 | E19: {=D2*D19} -> 4350
D23: {=210/6} -> 35

Sheet January
B2: Date | C2: Description | D2: Category | E2: Amount
B3: 1/29/26 | C3: Occhiali | D3: Personal Items | E3: 800
B4: 1/29/26 | C4: Apple creator studio | D4: Utilities & subscriptions | E4: 2.99
B5: 1/26/26 | C5: Analisi del sangue | D5: Medical | E5: 21.6
B6: 1/22/26 | C6: Spoty | D6: Utilities & subscriptions | E6: 20.99
B7: 1/20/26 | C7: Stay | D7: Other | E7: 21.84
B8: 1/20/26 | C8: Parcheggio | D8: Travel & auto | E8: 1.4
B9: 1/13/26 | C9: Stay | D9: Other | E9: 5.6
B10: 1/9/26 | C10: Intimissimi | D10: Personal Items | E10: 22.85
B11: 1/7/26 | C11: Autostrada | D11: Travel & auto | E11: 5.4
B12: 1/7/26 | C12: Discovery plus | D12: Entertainment | E12: 2.89
B13: 1/2/26 | C13: Stay | D13: Other/donations | E13: 30
B14: 1/1/26 | C14: Parcheggio | D14: Travel & auto | E14: 1.8
B15: 1/1/26 | C15: Stipendio | D15: Salary | E15: 597
F30: Expenses Summary by Category
F31: Category | G31: Budget | H31: Actual | I31: Difference
F32: Restaurant | G32: 0 | H32: {=SUMIF(D3:D28,$F32,E3:E28)} -> 0 | I32: {=G32-H32} -> 0
F33: Sport & Activities | G33: 8 | H33: 8 | I33: {=G33-H33} -> 0
F34: Food | G34: 0 | H34: {=SUMIF(D3:D28,$F34,E3:E28)} -> 0 | I34: {=G34-H34} -> 0
F35: Home | G35: 0 | H35: {=SUMIF(D3:D28,$F35,E3:E28)} -> 0 | I35: {=G35-H35} -> 0
F36: Medical | G36: {=H36} -> 21.6 | H36: {=SUMIF(D3:D28,$F36,E3:E28)} -> 21.6 | I36: {=G36-H36} -> 0
F37: Personal Items | G37: {=H37} -> 822.85 | H37: {=SUMIF(D3:D28,$F37,E3:E28)} -> 822.85 | I37: {=G37-H37} -> 0
F38: Travel & auto | G38: {=H38} -> 8.6 | H38: {=SUMIF(D3:D28,$F38,E3:E28)} -> 8.6 | I38: {=G38-H38} -> 0
F39: Utilities & subscriptions | G39: {=H39} -> 23.98 | H39: {=SUMIF(D3:D28,$F39,E3:E28)} -> 23.98 | I39: {=G39-H39} -> 0
F40: Other | G40: {=H40} -> 27.44 | H40: {=SUMIF(D3:D28,$F40,E3:E28)} -> 27.44 | I40: {=G40-H40} -> 0
F41: Total | G41: {=SUM(G32:G40)} -> 912.47 | H41: {=SUM(H32:H40)} -> 912.47 | I41: {=G41-H41} -> 0
J43: Income Summary
J44: Category | K44: Budget | L44: Actual | M44: Difference
J45: Salary | K45: 597 | L45: {=SUMIF(D3:D28,$J45,E3:E28)} -> 597 | M45: {=L45-K45} -> 0
J46: Other/donations | K46: 0 | L46: {=SUMIF(D3:D28,$J46,E3:E28)} -> 30 | M46: {=L46+K46} -> 30
J47: Total | K47: {=SUM(K45:K46)} -> 597 | L47: {=SUM(L45:L46)} -> 627 | M47: {=L47-K$47} -> 30

Sheet February
B2: Date | C2: Description | D2: Category | E2: Amount
B3: 46054 | C3: Plaza Cafe (caraglio) satispay | D3: Restaurant | E3: 4.3
B4: 46055 | C4: Regalo laurea gli (satispay) | D4: Other | E4: 20
B5: 46059 | C5: Prato nevoso (satispay) | D5: Sport & activities | E5: 23
B6: 46056 | C6: stipendio | D6: Salary | E6: 300
B7: 46056 | C7: Unieuro (sensore movimento) | D7: Home | E7: 19.99
B8: 46059 | C8: Amazon (sono relè) | D8: Home | E8: 16.14
B9: 46059 | C9: Paecheggio | D9: Travel & auto | E9: 0.51
B10: 46065 | C10: Paecheggio | D10: Travel & auto | E10: 1.91
B11: 46066 | C11: Paecheggio | D11: Travel & auto | E11: 1.4
B12: 46066 | C12: Paecheggio | D12: Travel & auto | E12: 0.77
B13: 46063 | C13: Pie | D13: Other | E13: 5.5
B14: 46067 | C14: prestofresco | D14: Food | E14: 1.89
... B20: 46077 | C20: Rimborso Livio gita movi | D20: Other/donations | E20: 13.9
B21: 46081 | D21: Other | E21: 2.99
B22: 46069 | C22: Autostrada torino | D22: Travel & auto | E22: 2.7
B23: 46076 | C23: Autostrada papà | D23: Travel & auto | E23: 0.72
B24: 46080 | C24: Prato nevoso (satispay) | D24: Sport & activities | E24: 23
B25: 46081 | C25: Acqua nonna ospedale | D25: Food | E25: {=0.57*3} -> 1.71
D26: Other/donations | E26: 8000
F31: Expenses Summary by Category
F32: Category | G32: Budget | H32: Actual | I32: Difference
F33: Restaurant | G33: {='Budgeting'!C3} -> 4.3 | H33: {=SUMIF(D3:D29,$F33,E3:E29)} -> 4.3 | I33: {=G33-H33} -> 0
F34: Sport & Activities | G34: {='Budgeting'!C4} -> 46 | H34: {=SUMIF(D3:D29,$F34,E3:E29)} -> 46 | I34: {=G34-H34} -> 0
F35: Food | G35: {='Budgeting'!C5} -> 4.6 | H35: {=SUMIF(D3:D29,$F35,E3:E29)} -> 4.6 | I35: {=G35-H35} -> 0
F36: Home | G36: {='Budgeting'!C6} -> 36.13 | H36: {=SUMIF(D3:D29,$F36,E3:E29)} -> 36.13 | I36: {=G36-H36} -> 0
F37: Medical | G37: {='Budgeting'!C7} -> 0 | H37: {=SUMIF(D3:D29,$F37,E3:E29)} -> 0 | I37: {=G37-H37} -> 0
F38: Personal Items | G38: {='Budgeting'!C8} -> 0 | H38: {=SUMIF(D3:D29,$F38,E3:E29)} -> 0 | I38: {=G38-H38} -> 0
F39: Travel & auto | G39: {='Budgeting'!C9} -> 10.36 | H39: {=SUMIF(D3:D29,$F39,E3:E29)} -> 10.36 | I39: {=G39-H39} -> 0
F40: Utilities & subscriptions | G40: {='Budgeting'!C10} -> 5 | H40: {=SUMIF(D3:D29,$F40,E3:E29)} -> 5 | I40: {=G40-H40} -> 0
F41: Other | G41: {='Budgeting'!C11} -> 32.49 | H41: {=SUMIF(D3:D29,$F41,E3:E29)} -> 32.49 | I41: {=G41-H41} -> 0
F42: Total | G42: {=SUM(G33:G41)} -> 138.88 | H42: {=SUM(H33:H41)} -> 138.88 | I42: {=G42-H42} -> 0
J44: Income Summary
J45: Category | K45: Budget | L45: Actual | M45: Difference
J46: Salary | K46: 300 | L46: {=SUMIF(D3:D29,$J46,E3:E29)} -> 300 | M46: {=L46-K46} -> 0
J47: Other/donations | K47: 0 | L47: {=SUMIF(D3:D29,$J47,E3:E29)} -> 8022.9 | M47: {=L47+K47} -> 8022.9
J48: Total | K48: {=SUM(K46:K47)} -> 300 | L48: {=SUM(L46:L47)} -> 8322.9 | M48: {=L48-K$48} -> 8022.9

Sheet March
B2: Date | C2: Description | D2: Category | E2: Amount
B3: 46085 | C3: Amazon (creaplus e quaderno buste) | D3: Personal Items | E3: 30.83
B4: 46085 | C4: Insurance | D4: Medical | E4: 568.82
B5: 46086 | C5: Regalo laurea jack | D5: Other | E5: 25
B6: 46087 | C6: Revolv collaborazione occasionale | D6: Salary | E6: 1568
B7: 46088 | C7: Cena jolly piovani | D7: Restaurant | E7: 9.65
B8: 46088 | C8: Perplexity | D8: Utilities & subscriptions | E8: 10.92
B9: 46089 | C9: RESTO TORTA GIO | D9: Other/donations | E9: 5
B10: 46091 | C10: Prato nevoso (satispay) | D10: Sport & activities | E10: 23
B11: 46092 | C11: Presto fresco | D11: Food | E11: 2.48
B12: 46093 | C12: Tassa SEVIS | D12: Other | E12: 304.08
B13: 46093 | C13: Parcheggio | D13: Travel & auto | E13: 0.6
B14: 46094 | C14: Tassa visto | D14: Other | E14: 175
... B20: 46822 | C20: Cover iPhone | D20: Personal Items | E20: 23.15
B21: 17/03/26 | C21: Birreria Moulin | D21: Restaurant | E21: 10.5
B22: 17/03/26 | C22: Satisfy | E22: 36.08
B23: 20/03/26 | C23: Cless Ticket Atm Milan Milano | D23: Travel & auto | E23: 6.6
B24: 20/03/26 | C24: Mango Milan Corso 2 St Milano | D24: Personal Items | E24: 122.12
B25: 20/03/26 | C25: Buffet Torino Porta Susa | D25: Restaurant | E25: 7.3
B26: 20/03/26 | C26: Eatme Milano Srl Galleria P | D26: Restaurant | E26: 4.6
B27: 22/03/26 | C27: Biglietti baseball | D27: Entertainment | E27: 69.23
B28: 24/03/26 | C28: Cless Ticket Atm Milano Milano | D28: Travel & auto | E28: 1.3
B29: 24/03/26 | C29: Spotify | D29: Utilities & subscriptions | E29: 20.99
B30: 27/03/26 | C30: Parcheggio torino | D30: Travel & auto | E30: 5
B31: 28/03/26 | C31: Cn Parcheggio Movicentro Cuneo | D31: Travel & auto | E31: 0.85
B32: 28/03/26 | C32: Mercato' Extra Cuneo V Vi | D32: Food | E32: 88.97
B33: 28/03/26 | C33: Mani Corso Giolitti 19 Cun | D33: Personal Items | E33: 20
B34: 29/03/26 | C34: Amazon Creme | D34: Personal Items | E34: 32.6
... B41: 31/03/27 | C41: Ristorante papà | D41: Restaurant | E41: 51.79
F43: Expenses Summary by Category
F44: Category | G44: Budget | H44: Actual | I44: Difference
F45: Restaurant | G45: {='Budgeting'!D3} -> 99.64 | H45: {=SUMIF(D3:D41,$F45,E3:E41)} -> 99.64 | I45: {=G45-H45} -> 0
F46: Sport & Activities | G46: {='Budgeting'!D4} -> 23 | H46: {=SUMIF(D3:D41,$F46,E3:E41)} -> 23 | I46: {=G46-H46} -> 0
F47: Food | G47: {='Budgeting'!D5} -> 91.45 | H47: {=SUMIF(D3:D41,$F47,E3:E41)} -> 91.45 | I47: {=G47-H47} -> 0
F48: Home | G48: {='Budgeting'!D6} -> 0 | H48: {=SUMIF(D3:D41,$F48,E3:E41)} -> 0 | I48: {=G48-H48} -> 0
F49: Medical | G49: {='Budgeting'!D7} -> 568.82 | H49: {=SUMIF(D3:D41,$F49,E3:E41)} -> 568.82 | I49: {=G49-H49} -> 0
F50: Personal Items | G50: {='Budgeting'!D8} -> 295.45 | H50: {=SUMIF(D3:D41,$F50,E3:E41)} -> 295.45 | I50: {=G50-H50} -> 0
F51: Travel & auto | G51: {='Budgeting'!D9} -> 14.35 | H51: {=SUMIF(D3:D41,$F51,E3:E41)} -> 14.35 | I51: {=G51-H51} -> 0
F52: Utilities & subscriptions | G52: {='Budgeting'!D10} -> 39.9 | H52: {=SUMIF(D3:D41,$F52,E3:E41)} -> 39.9 | I52: {=G52-H52} -> 0
F53: Other | G53: {='Budgeting'!D11} -> 557.98 | H53: {=SUMIF(D3:D41,$F53,E3:E41)} -> 557.98 | I53: {=G53-H53} -> 0
...

Sheet April
B2: Date | C2: Description | D2: Category | E2: Amount | F2: Conversione | G2: Dollars | H2: Conto
B3: 46113 | C3: Caffe | D3: Restaurant | E3: 2.66
B4: 46113 | C4: Caffe | D4: Restaurant | E4: 2.66 | H4: R
B5: 46114 | C5: Pranzo santa monica | D5: Restaurant | E5: 39.47
B6: 46115 | C6: Starbucks | D6: Restaurant | E6: 4.23
B7: 46116 | C7: Telefono | D7: Utilities & subscriptions | E7: 17.62 | H7: R
B8: 46116 | C8: Coffee bean | D8: Restaurant | E8: 4.11
B9: 46117 | C9: Waymo | D9: Travel & auto | E9: 6.52
B10: 46117 | C10: Adobe *adobe Dublin | D10: Personal Items | E10: 145.52
B11: 46118 | C11: Starbucks | D11: Restaurant | E11: 5.45
B12: 46119 | C12: Caffe ufficio cialde | D12: Restaurant | E12: 24.5 | H12: R
B13: 46119 | C13: La metro mobile app | D13: Restaurant | E13: 1.38
B14: 46119 | C14: Pranzo JPL | D14: Restaurant | E14: 8.27
B15: 46119 | C15: Caffe JPL | D15: Restaurant | E15: 2.64
B16: 46120 | C16: Airbnb | D16: Home | E16: 1828.71
B17: 46120 | C17: JPL pranzo | D17: Restaurant | E17: 5.29
B18: 46120 | C18: Satispay | D18: Other | E18: 21.9
B19: 46121 | C19: Pranzo JPL | D19: Restaurant | E19: 12.33
B20: 46121 | C20: LA metro | D20: Travel & auto | E20: 4.32
B21: 46122 | C21: JPL caffe | D21: Restaurant | E21: 2.31
B22: 46122 | C22: JPL caffe | D22: Restaurant | E22: 2.32
B23: 46122 | C23: Spesa Vons | D23: Food | E23: 40.1
B24: 46123 | C24: Amtrak treno san Diego | D24: Travel & auto | E24: 30.83
... B27: 46123 | C27: Target | D27: Home | E27: 38.58
B28: 46124 | C28: Uscita san diego | D28: Other | E28: {=G28*F28} -> 14.074821 | F28: {='Budgeting'!$AH$51} -> 0.85822078 | G28: 16.4 | H28: R
B29: 46124 | C29: Vons spes | D29: Food | E29: 46.26
B30: 46124 | C30: Vons pranzo san diego | D30: Restaurant | E30: 2.53
B31: 46124 | C31: Doritos treno | D31: Restaurant | E31: 3
B32: 46125 | C32: Coffee Bean & Tea Pasadena | D32: Restaurant | E32: 4.06
B33: 46125 | C33: Trader Joe S #179 | D33: Food | E33: 3.52
B34: 46126 | C34: Perplexity | D34: Utilities & subscriptions | E34: 10.92
B35: 46126 | C35: Discovery plus | D35: Utilities & subscriptions | E35: 2.89
B36: 46127 | C36: Tours* Dixieslowerante Gilbert - maggio | D36: Other | E36: 70.85
B37: 46128 | C37: Poker | D37: Other | E37: {=G37*F37} -> 3.261239 | F37: {='Budgeting'!$AH$51} -> 0.85822078 | G37: 3.8 | H37: R
B38: 46128 | C38: Jpl Cafe 303 Orbit | D38: Restaurant | E38: 7.04
B39: 46128 | C39: Pavilions #2224 | D39: Food | E39: 11.27
B40: 46129 | C40: Grigliata casa italiani | D40: Restaurant | E40: {=G40*F40} -> 9.869539 | F40: {='Budgeting'!$AH$51} -> 0.85822078 | G40: 11.5 | H40: R
B41: 46129 | C41: Biglietti lakers quota Anna | D41: Other/donations | E41: {=G41*F41} -> 105.56116 | F41: {='Budgeting'!$AH$51} -> 0.85822078 | G41: 123 | H41: R
B42: 46130 | C42: Dominos | D42: Restaurant | E42: {=G42*F42} -> 5.4754486 | F42: {='Budgeting'!$AH$51} -> 0.85822078 | G42: 6.38 | H42: R
B43: 46130 | C43: Lakers | D43: Other | E43: 215.37
...

Sheet May
B2: Date | C2: Description | D2: Category | E2: Amount
B3: 46143.5 | C3: Rtc Southern Nevada (Bus las vegas) | D3: Travel & auto | E3: {=F3*G3} -> 6.8657663 | F3: {='Budgeting'!$AH$51} -> 0.85822078 | G3: 8 | H3: R
B4: 46143.75 | C4: McDonald’s (las vegas) | D4: Restaurant | E4: {=F4*G4} -> 1.4761397 | F4: {='Budgeting'!$AH$51} -> 0.85822078 | G4: 1.72 | H4: R
B5: 46143.916 | C5: Burger King (St George) | D5: Restaurant | E5: {=F5*G5} -> 4.6172278 | F5: {='Budgeting'!$AH$51} -> 0.85822078 | G5: 5.38 | H5: R
B6: 46143.688 | C6: Welcome To Lv @foru 282 (Souvenir) | D6: Personal Items | E6: {=F6*G6} -> 2.7892175 | F6: {='Budgeting'!$AH$51} -> 0.85822078 | G6: 3.25 | H6: R
B7: 46142.754 | C7: Trader Joe’s | D7: Food | E7: {=F7*G7} -> 3.7847537 | F7: {='Budgeting'!$AH$51} -> 0.85822078 | G7: 4.41 | H7: R
B8: 46144.673 | C8: McDonald's Page | D8: Restaurant | E8: {=F8*G8} -> 0.95262507 | F8: {='Budgeting'!$AH$51} -> 0.85822078 | G8: 1.11 | H8: R
B9: 46144.749 | C9: Visible Cellulare | D9: Utilities & subscriptions | E9: {=F9*G9} -> 17.164416 | F9: {='Budgeting'!$AH$51} -> 0.85822078 | G9: 20 | H9: R
B10: 46145.802 | C10: Vons Spesa | D10: Food | E10: {=F10*G10} -> 8.7710164 | F10: {='Budgeting'!$AH$51} -> 0.85822078 | G10: 10.22 | H10: R
B11: 46145.522 | C11: Subway Pranzo Las Vegas | D11: Restaurant | E11: {=F11*G11} -> 8.6851943 | F11: {='Budgeting'!$AH$51} -> 0.85822078 | G11: 10.12 | H11: R
B12: 46146.385 | C12: Jpl Coffee Cart | D12: Restaurant | E12: {=F12*G12} -> 2.3171961 | F12: {='Budgeting'!$AH$51} -> 0.85822078 | G12: 2.7 | H12: R
B13: 46146.788 | C13: Caltech Gym Mem. Cc | D13: Sport & activities | E13: {=F13*G13} -> 85.822078 | F13: {='Budgeting'!$AH$51} -> 0.85822078 | G13: 100 | H13: R
B14: 46146.822 | C14: Commissioni bonifici | D14: Other | E14: {=F14*G14} -> 2.9522795 | F14: {='Budgeting'!$AH$51} -> 0.85822078 | G14: 3.44 | H14: R
... B17: 46147.914 | C17: Vons Spesa | D17: Food | E17: {=F17*G17} -> 46.155114 | F17: {='Budgeting'!$AH$51} -> 0.85822078 | G17: 53.78 | H17: R
B18: 46147.914 | C18: Walgreens juul | D18: Other | E18: 42.58 | F18: {='Budgeting'!$AH$51} -> 0.85822078 | H18: R
B19: 46151.018 | C19: Transfer to ANDREA GALENDA beer | D19: Restaurant | E19: {=G19*F19} -> 11.15687 | F19: {='Budgeting'!$AH$51} -> 0.85822078 | G19: 13 | H19: R
B20: 46151.028 | C20: Transfer to ANDREA GALENDA biliardo | D20: Restaurant | E20: {=G20*F20} -> 2.145552 | F20: {='Budgeting'!$AH$51} -> 0.85822078 | G20: 2.5 | H20: R
B21: 46149.48 | C21: Jpl Retail shop tazzina | D21: Personal Items | E21: {=G21*F21} -> 6.0676209 | F21: {='Budgeting'!$AH$51} -> 0.85822078 | G21: 7.07 | H21: R
B22: 46150.801 | C22: Amazon | D22: Food | E22: {=G22*F22} -> 8.9426606 | F22: {='Budgeting'!$AH$51} -> 0.85822078 | G22: 10.42 | H22: R
B23: 46150.947 | C23: Barneys Beanery Beer | D23: Restaurant | E23: {=G23*F23} -> 7.2948767 | F23: {='Budgeting'!$AH$51} -> 0.85822078 | G23: 8.5 | H23: R
B24: 46150.943 | C24: Barney's Beanery Entrance | D24: Restaurant | E24: {=G24*F24} -> 4.2911039 | F24: {='Budgeting'!$AH$51} -> 0.85822078 | G24: 5 | H24: R
B25: 46151.894 | C25: Shake Shack | D25: Restaurant | E25: {=G25*F25} -> 17.215909 | F25: {='Budgeting'!$AH$51} -> 0.85822078 | G25: {=23.56-3.5} -> 20.06 | H25: R meno pata Anna
B26: 46150.797 | C26: Amazon | D26: Food | E26: {=G26*F26} -> 10.161334 | F26: {='Budgeting'!$AH$51} -> 0.85822078 | G26: 11.84 | H26: R
B27: 46152.551 | C27: Vons | D27: Food | E27: {=G27*F27} -> 8.9169139 | F27: {='Budgeting'!$AH$51} -> 0.85822078 | G27: {=20.68-5-5.29} -> 10.39 | H27: R tolto anna e fra
B28: 46152.818 | C28: Vons | D28: Food | E28: {=G28*F28} -> 18.065547 | F28: {='Budgeting'!$AH$51} -> 0.85822078 | G28: 21.05 | H28: R
B29: 46152.819 | C29: Vons | D29: Food | E29: {=G29*F29} -> 5.8788124 | F29: {='Budgeting'!$AH$51} -> 0.85822078 | G29: 6.85 | H29: R
B30: 46151.973 | C30: Shoo Shoo Baby Beer los angeles | D30: Restaurant | E30: {=G30*F30} -> 9.4404286 | F30: {='Budgeting'!$AH$51} -> 0.85822078 | G30: 11 | H30: R
B31: 46156.661 | C31: Transfer to PABLO SCHERPEREEL ARCE per rocket | D31: Personal Items | E31: {=G31*F31} -> 80.844398 | F31: {='Budgeting'!$AH$51} -> 0.85822078 | G31: 94.2
B32: 46156.031 | C32: Amazon Borraccia | D32: Personal Items | E32: {=G32*F32} -> 14.169225 | F32: {='Budgeting'!$AH$51} -> 0.85822078 | G32: {=24.48-7.97} -> 16.51 | H32: Meno tonno Anna
B33: 46156.411 | C33: Amazon | E33: {=G33*F33} -> 4.2739395 | F33: {='Budgeting'!$AH$51} -> 0.85822078 | G33: 4.98 | H33: Spesa anna
B34: 46156.009 | C34: Amazon | D34: Food | E34: {=G34*F34} -> 4.8146186 | F34: {='Budgeting'!$AH$51} -> 0.85822078 | G34: 5.61
B35: 46156.574 | C35: Amazon tenda e tonno | D35: Personal Items | E35: {=G35*F35} -> 38.122167 | F35: {='Budgeting'!$AH$51} -> 0.85822078 | G35: 44.42
B36: 46157.424 | C36: Panamint campeggio | D36: Travel & auto | E36: {=G36*F36} -> 3.6780891 | F36: {='Budgeting'!$AH$51} -> 0.85822078 | G36: {=30/7} -> 4.2857143 | H36: Dv
B37: 46157.023 | C37: Amazon rimborso | E37: {=G37*F37} -> 36.019526 | F37: {='Budgeting'!$AH$51} -> 0.85822078 | G37: {=41.97} -> 41.97 | H37: Rimborso batteria fra
B38: 46157.426 | C38: ALDI | D38: Food | E38: {=G38*F38} -> 8.9855716 | F38: {='Budgeting'!$AH$51} -> 0.85822078 | G38: 10.47
B39: 46157.426 | C39: Spesa condivisa ALDI | D39: Food | E39: {=G39*F39} -> 3.0810126 | F39: {='Budgeting'!$AH$51} -> 0.85822078 | G39: {=25.13/7} -> 3.59
B40: 46157.426 | C40: Macchina Thibault | D40: Travel & auto | E40: {=G40*F40} -> 30.895948 | F40: {='Budgeting'!$AH$51} -> 0.85822078 | G40: 36
B41: 46160.814 | C41: Transfer to FRANCESCO PISACANE rimborso batteria | E41: {=G41*F41} -> 31.728422 | F41: {='Budgeting'!$AH$51} -> 0.85822078 | G41: 36.97 | H41: Gia tolti rimborso meno pizza
B42: 46160.84 | C42: Transfer from ANNA MOSCATI | E42: {=G42*F42} -> 62.358322 | F42: {='Budgeting'!$AH$51} -> 0.85822078 | G42: 72.66 | H42: Gia tolti
B43: 46160.95 | C43: Transfer from LOU-ANN JEANNE DOMINIQUE PARIETTI | E43: {=G43*F43} -> 32.809781 | F43: {='Budgeting'!$AH$51} -> 0.85822078 | G43: 38.23 | H43: Gia tolti
...

Sheet June
B2: Date | C2: Description | D2: Category | E2: Amount
B3: 46175.455 | C3: Amazon | D3: Food | E3: {=F3*G3} -> 8.3247416 | F3: {='Budgeting'!$AH$51} -> 0.85822078 | G3: 9.7 | H3: R
B4: 46175.462 | C4: Amazon | D4: Other | E4: {=F4*G4} -> 15.164761 | F4: {='Budgeting'!$AH$51} -> 0.85822078 | G4: 17.67 | H4: R
B5: 46175.752 | C5: Visible | D5: Utilities & subscriptions | E5: {=F5*G5} -> 17.164416 | F5: {='Budgeting'!$AH$51} -> 0.85822078 | G5: 20 | H5: R
B6: 46176.764 | C6: Target | D6: Food | E6: {=F6*G6} -> 15.6282 | F6: {='Budgeting'!$AH$51} -> 0.85822078 | G6: 18.21 | H6: R
B7: 46175.751 | C7: Vons | D7: Food | E7: {=F7*G7} -> 17.130087 | F7: {='Budgeting'!$AH$51} -> 0.85822078 | G7: 19.96 | H7: R
B8: 46177.343 | C8: Tap Transit | D8: Travel & auto | E8: {=F8*G8} -> 2.145552 | F8: {='Budgeting'!$AH$51} -> 0.85822078 | G8: 2.5 | H8: R
B9: 46178.295 | C9: Recreation,gov | D9: Travel & auto | E9: {=F9*G9} -> 17.164416 | F9: {='Budgeting'!$AH$51} -> 0.85822078 | G9: 20 | H9: 40-20 di fra
B10: 46178.297 | C10: Transfer from FRANCESCO PISACANE | E10: {=F10*G10} -> 17.164416 | F10: {='Budgeting'!$AH$51} -> 0.85822078 | G10: 20 | H10: R
B11: 46178.466 | C11: Amazon | D11: Other | E11: {=F11*G11} -> 26.544769 | F11: {='Budgeting'!$AH$51} -> 0.85822078 | G11: 30.93 | H11: R
B12: 46178.528 | C12: Jpl Cafe 303 Orbit | D12: Restaurant | E12: {=F12*G12} -> 7.5780895 | F12: {='Budgeting'!$AH$51} -> 0.85822078 | G12: 8.83 | H12: R
B13: 46178.762 | C13: Vons | D13: Other | E13: {=F13*G13} -> 2.8321286 | F13: {='Budgeting'!$AH$51} -> 0.85822078 | G13: 3.3 | H13: R
B14: 46178.782 | C14: Amazon | D14: Food | E14: {=F14*G14} -> 3.1668347 | F14: {='Budgeting'!$AH$51} -> 0.85822078 | G14: 3.69 | H14: R
B15: 46178.806 | C15: Amazon | D15: Food | E15: {=F15*G15} -> 21.438355 | F15: {='Budgeting'!$AH$51} -> 0.85822078 | G15: 24.98 | H15: R
B16: 46172 | C16: Affitto | D16: Home | E16: 948.5 | F16: {='Budgeting'!$AH$51} -> 0.85822078 | H16: R
B17: 46179.83 | C17: La Perla Cocina #2 | D17: Restaurant | E17: {=F17*G17} -> 14.100567 | F17: {='Budgeting'!$AH$51} -> 0.85822078 | G17: 16.43 | H17: R
B18: 46180.013 | C18: Moonshine Flats Ga Discoteca san diego | D18: Travel & auto | E18: {=F18*G18} -> 8.5822078 | F18: {='Budgeting'!$AH$51} -> 0.85822078 | G18: 10 | H18: R
B19: 46180.023 | C19: Moonshine Flats Ga Discoteca san diego | D19: Restaurant | E19: {=G19*F19} -> 7.8527202 | F19: {='Budgeting'!$AH$51} -> 0.85822078 | G19: 9.15 | H19: R
B20: 46180.614 | C20: Mike Hess Brewing | D20: Restaurant | E20: {=G20*F20} -> 7.3120411 | F20: {='Budgeting'!$AH$51} -> 0.85822078 | G20: 8.52 | H20: R
B21: 46181.73 | C21: Transfer to ANDREA GALENDA Caffe pod | D21: Food | E21: {=G21*F21} -> 14.323705 | F21: {='Budgeting'!$AH$51} -> 0.85822078 | G21: 16.69 | H21: R
B22: 46182.61 | C22: Transfer to VINCENZO POLIZZI San diego trip | D22: Travel & auto | E22: {=G22*F22} -> 68.391614 | F22: {='Budgeting'!$AH$51} -> 0.85822078 | G22: 79.69 | H22: R
B23: 46182.755 | C23: Vallarta Vfe 51 | D23: Food | E23: {=G23*F23} -> 27.557469 | F23: {='Budgeting'!$AH$51} -> 0.85822078 | G23: 32.11 | H23: R
B24: 46182.803 | C24: Amazon | D24: Food | E24: {=G24*F24} -> 30.750051 | F24: {='Budgeting'!$AH$51} -> 0.85822078 | G24: 35.83 | H24: R
B25: 46182.807 | C25: Amazon | D25: Food | E25: {=G25*F25} -> 15.422227 | F25: {='Budgeting'!$AH$51} -> 0.85822078 | G25: 17.97 | H25: R
B26: 46183.532 | C26: Amazon | D26: Food | E26: {=G26*F26} -> 23.695476 | F26: {='Budgeting'!$AH$51} -> 0.85822078 | G26: 27.61 | H26: R
B27: 46183.891 | C27: Ralphs | D27: Food | E27: {=G27*F27} -> 20.528641 | F27: {='Budgeting'!$AH$51} -> 0.85822078 | G27: 23.92 | H27: R
B28: 46184.519 | C28: Jpl Cafe 303 Orbit | D28: Restaurant | E28: {=G28*F28} -> 1.8966679 | F28: {='Budgeting'!$AH$51} -> 0.85822078 | G28: 2.21 | H28: R
B29: 46184.701 | C29: CVS Pharmacy | D29: Personal Items | E29: {=G29*F29} -> 8.3247416 | F29: {='Budgeting'!$AH$51} -> 0.85822078 | G29: 9.7 | H29: R
B30: 46185.915 | C30: Fig Garden Village | D30: Restaurant | E30: {=G30*F30} -> 4.1022953 | F30: {='Budgeting'!$AH$51} -> 0.85822078 | G30: 4.78 | H30: R
B31: 46186.776 | C31: Fig Garden Village | D31: Restaurant | E31: {=G31*F31} -> 18.237192 | F31: {='Budgeting'!$AH$51} -> 0.85822078 | G31: 21.25
B32: 46187.852 | C32: In-n-Out Burger | D32: Restaurant | E32: {=G32*F32} -> 10.401636 | F32: {='Budgeting'!$AH$51} -> 0.85822078 | G32: 12.12
B33: 46187.941 | C33: Transfer to FRANCESCO PISACANE | D33: Food | E33: {=G33*F33} -> 5.4067909 | F33: {='Budgeting'!$AH$51} -> 0.85822078 | G33: 6.3
B34: 46188.469 | C34: Transfer to FRANCESCO PISACANE | D34: Travel & auto | E34: {=G34*F34} -> 61.036662 | F34: {='Budgeting'!$AH$51} -> 0.85822078 | G34: 71.12
B35: 46189.939 | C35: Amazon | D35: Food | E35: {=G35*F35} -> 8.9855716 | F35: {='Budgeting'!$AH$51} -> 0.85822078 | G35: 10.47
B36: 46190.066 | C36: Amazon | D36: Food | E36: {=G36*F36} -> 17.507704 | F36: {='Budgeting'!$AH$51} -> 0.85822078 | G36: 20.4 | H36: Dv
B37: 46190.153 | C37: Amazon | D37: Food | E37: {=G37*F37} -> 15.422227 | F37: {='Budgeting'!$AH$51} -> 0.85822078 | G37: 17.97
B38: 46190.486 | C38: Amazon | D38: Food | E38: {=G38*F38} -> 2.8321286 | F38: {='Budgeting'!$AH$51} -> 0.85822078 | G38: 3.3
B39: 46190.877 | C39: Transfer from ANDREA GALENDA | D39: Other/donations | E39: {=G39*F39} -> 7.2948767 | F39: {='Budgeting'!$AH$51} -> 0.85822078 | G39: 8.5
B40: 46191.929 | C40: Transfer to MATTEO GIOVANNI JUVARA sushi | D40: Restaurant | E40: {=G40*F40} -> 24.545114 | F40: {='Budgeting'!$AH$51} -> 0.85822078 | G40: 28.6
B41: 46192.457 | C41: Ca Dmv 509 | D41: Personal Items | E41: {=G41*F41} -> 34.328831 | F41: {='Budgeting'!$AH$51} -> 0.85822078 | G41: 40
...

Sheet July
B2: Date | C2: Description | D2: Category | E2: Amount
B3: 46204.101 | C3: Amazon | D3: Food | E3: {=G3*F3} -> 5.1149959 | F3: {='Budgeting'!$AH$51} -> 0.85822078 | G3: 5.96 | H3: R
B4: 46204.31 | C4: Amazon | D4: Food | E4: {=G4*F4} -> 41.100193 | F4: {='Budgeting'!$AH$51} -> 0.85822078 | G4: 47.89 | H4: R
B5: 46204.76 | C5: Target | D5: Personal Items | E5: {=G5*F5} -> 16.057311 | F5: {='Budgeting'!$AH$51} -> 0.85822078 | G5: 18.71 | H5: R
B6: 46205.441 | C6: Transfer to MARCO CORAIOLA | D6: Personal Items | E6: {=G6*F6} -> 4.4455837 | F6: {='Budgeting'!$AH$51} -> 0.85822078 | G6: 5.18 | H6: R
B7: 46205.453 | C7: Jpl Cafe 303 Orbit | D7: Restaurant | E7: {=G7*F7} -> 8.6766121 | F7: {='Budgeting'!$AH$51} -> 0.85822078 | G7: 10.11 | H7: R
B8: 46205.754 | C8: Maverik | D8: Restaurant | E8: {=G8*F8} -> 1.8537569 | F8: {='Budgeting'!$AH$51} -> 0.85822078 | G8: 2.16 | H8: R
B9: 46206.132 | C9: Maverik | D9: Restaurant | E9: {=G9*F9} -> 1.8108459 | F9: {='Budgeting'!$AH$51} -> 0.85822078 | G9: 2.11 | H9: R
B10: 46206.316 | C10: Visible | D10: Utilities & subscriptions | E10: {=G10*F10} -> 17.164416 | F10: {='Budgeting'!$AH$51} -> 0.85822078 | G10: 20 | H10: R
B11: 46206.525 | C11: Marriott Bonvoy Hotels | D11: Travel & auto | E11: {=(G11*F11)-90-89.7} -> 39.832876 | F11: {='Budgeting'!$AH$51} -> 0.85822078 | G11: 255.8 | H11: R
B12: 46206.619 | C12: Bozeman Convention & Visitors Bureau | D12: Personal Items | E12: {=G12*F12} -> 2.7463065 | F12: {='Budgeting'!$AH$51} -> 0.85822078 | G12: 3.2 | H12: R
B13: 46206.637 | C13: Old Faithful Snow Lodge | D13: Personal Items | E13: {=G13*F13} -> 16.52075 | F13: {='Budgeting'!$AH$51} -> 0.85822078 | G13: 19.25 | H13: R
B14: 46206.643 | C14: Bozeman Convention & Visitors Bureau | D14: Food | E14: {=G14*F14} -> 6.8571841 | F14: {='Budgeting'!$AH$51} -> 0.85822078 | G14: 7.99 | H14: R
B15: 46207.624 | C15: Canyon General Mini-Mart | D15: Food | E15: {=G15*F15} -> 17.095758 | F15: {='Budgeting'!$AH$51} -> 0.85822078 | G15: 19.92 | H15: R
B16: 46208.934 | C16: Jack in the Box | D16: Restaurant | E16: {=G16*F16} -> 11.15687 | F16: {='Budgeting'!$AH$51} -> 0.85822078 | G16: 13 | H16: R
B17: 46209.924 | C17: Amazon | D17: Food | E17: {=G17*F17} -> 2.5660801 | F17: {='Budgeting'!$AH$51} -> 0.85822078 | G17: 2.99 | H17: R
B18: 46209.938 | C18: Amazon | D18: Food | E18: {=G18*F18} -> 22.46822 | F18: {='Budgeting'!$AH$51} -> 0.85822078 | G18: 26.18 | H18: R
B19: 46209.983 | C19: Amazon | D19: Food | E19: {=G19*F19} -> 3.4243009 | F19: {='Budgeting'!$AH$51} -> 0.85822078 | G19: 3.99 | H19: R
B20: 46210.149 | C20: Amazon | D20: Food | E20: {=G20*F20} -> 9.3374421 | F20: {='Budgeting'!$AH$51} -> 0.85822078 | G20: 10.88 | H20: R
B21: 46210.89 | C21: Amazon | D21: Food | E21: {=G21*F21} -> 18.837946 | F21: {='Budgeting'!$AH$51} -> 0.85822078 | G21: 21.95 | H21: R
B22: 46210.903 | C22: Amazon | D22: Food | E22: {=G22*F22} -> 3.4071365 | F22: {='Budgeting'!$AH$51} -> 0.85822078 | G22: 3.97 | H22: R
B23: 46210.951 | C23: Transfer to FRANCESCO PISACANE | D23: Travel & auto | E23: {=G23*F23} -> 83.805259 | F23: {='Budgeting'!$AH$51} -> 0.85822078 | G23: 97.65 | H23: R
... B27: 46212.311 | C27: Transfer to Matthew Fernandez | D27: Restaurant | E27: {=G27*F27} -> 6.4366559 | F27: {='Budgeting'!$AH$51} -> 0.85822078 | G27: 7.5 | H27: R
B28: 46212.909 | C28: Milt`s Liquor | D28: Restaurant | E28: {=G28*F28/4} -> 5.2995133 | F28: {='Budgeting'!$AH$51} -> 0.85822078 | G28: 24.7 | H28: R
B29: 46213.476 | C29: Amazon | D29: Food | E29: {=G29*F29} -> 7.226219 | F29: {='Budgeting'!$AH$51} -> 0.85822078 | G29: 8.42
B30: 46213.494 | C30: Amazon | D30: Food | E30: {=G30*F30} -> 25.901103 | F30: {='Budgeting'!$AH$51} -> 0.85822078 | G30: 30.18
B31: 46214.752 | C31: Recreation,gov | D31: Travel & auto | E31: {=G31*F31} -> 25.746623 | F31: {='Budgeting'!$AH$51} -> 0.85822078 | G31: 30
B32: 46215.382 | C32: Transfer to Matthew Fernandez | D32: Restaurant | E32: {=G32*F32} -> 5.7929903 | F32: {='Budgeting'!$AH$51} -> 0.85822078 | G32: 6.75
B33: 46203 | C33: Bonifico istantaneo da voi disposto a favore di Andrea Galenda | D33: Home | E33: 980
B34: 46215.382 | C34: Transfer to Andrea | D34: Restaurant | E34: {=G34*F34} -> 3.6474383 | F34: {='Budgeting'!$AH$51} -> 0.85822078 | G34: 4.25
B35: 46215.382 | C35: Vallarta Lasagna | D35: Food | E35: {=G35*F35} -> 54.994788 | F35: {='Budgeting'!$AH$51} -> 0.85822078 | G35: 64.08
B36: 46215.382 | C36: Vallarta Lasagna | D36: Food | E36: {=G36*F36} -> 7.7068226 | F36: {='Budgeting'!$AH$51} -> 0.85822078 | G36: 8.98
B37: 46215.382 | C37: Vallarta | D37: Food | E37: {=G37*F37} -> 11.946433 | F37: {='Budgeting'!$AH$51} -> 0.85822078 | G37: 13.92
B38: 46217.771 | C38: Amazon | D38: Food | E38: {=G38*F38} -> 7.9557067 | F38: {='Budgeting'!$AH$51} -> 0.85822078 | G38: 9.27
B39: 46218.704 | C39: Transfer to Matthew Fernandez - bbq | D39: Restaurant | E39: {=G39*F39} -> 8.5822078 | F39: {='Budgeting'!$AH$51} -> 0.85822078 | G39: 10
B40: 46218.628 | C40: Amazon | D40: Food | E40: {=G40*F40} -> 35.075483 | F40: {='Budgeting'!$AH$51} -> 0.85822078 | G40: 40.87
B41: 46219.936 | C41: Transfer from ANDREA GALENDA | D41: Other/donations | E41: {=G41*F41} -> 43.76926 | F41: {='Budgeting'!$AH$51} -> 0.85822078 | G41: 51
B42: 46219.787 | C42: Costco | D42: Restaurant | E42: {=G42*F42} -> 20.159606 | F42: {='Budgeting'!$AH$51} -> 0.85822078 | G42: 23.49
B43: 46219.785 | C43: Costco | D43: Food | E43: {=G43*F43} -> 60.839271 | F43: {='Budgeting'!$AH$51} -> 0.85822078 | G43: 70.89
B44: 46220.175 | C44: Amazon | D44: Food | E44: {=G44*F44} -> 35.075483 | F44: {='Budgeting'!$AH$51} -> 0.85822078 | G44: 40.87
...

Sheet August
B2: Date | C2: Description | D2: Category | E2: Amount
F30: Expenses Summary by Category
F31: Category | G31: Budget | H31: Actual | I31: Difference
F32: Restaurant | G32: {='Budgeting'!I3} -> 139.2 | H32: {=SUMIF(D3:D28,$F32,E3:E28)} -> 0 | I32: {=G32-H32} -> 139.2
F33: Sport & Activities | G33: {='Budgeting'!I4} -> 0 | H33: {=SUMIF(D3:D28,$F33,E3:E28)} -> 0 | I33: {=G33-H33} -> 0
F34: Food | G34: {='Budgeting'!I5} -> 287.1 | H34: {=SUMIF(D3:D28,$F34,E3:E28)} -> 0 | I34: {=G34-H34} -> 287.1
F35: Home | G35: {='Budgeting'!I6} -> 1000 | H35: {=SUMIF(D3:D28,$F35,E3:E28)} -> 0 | I35: {=G35-H35} -> 1000
F36: Medical | G36: {='Budgeting'!I7} -> 0 | H36: {=SUMIF(D3:D28,$F36,E3:E28)} -> 0 | I36: {=G36-H36} -> 0
F37: Personal Items | G37: {='Budgeting'!I8} -> 0 | H37: {=SUMIF(D3:D28,$F37,E3:E28)} -> 0 | I37: {=G37-H37} -> 0
F38: Travel & auto | G38: {='Budgeting'!I9} -> 278.4 | H38: {=SUMIF(D3:D28,$F38,E3:E28)} -> 0 | I38: {=G38-H38} -> 278.4
F39: Utilities & subscriptions | G39: {='Budgeting'!I10} -> 81.78 | H39: {=SUMIF(D3:D28,$F39,E3:E28)} -> 0 | I39: {=G39-H39} -> 81.78
F40: Other | G40: {='Budgeting'!I11} -> 87 | H40: {=SUMIF(D3:D28,$F40,E3:E28)} -> 0 | I40: {=G40-H40} -> 87
F41: Investment | G41: {='Budgeting'!I12} -> 0 | H41: {=SUMIF(D3:D28,$F41,E3:E28)} -> 0 | I41: {=G41-H41} -> 0
F42: Total | G42: {=SUM(G32:G41)} -> 1873.48 | H42: {=SUM(H32:H41)} -> 0 | I42: {=G42-H42} -> 1873.48
J44: Income Summary
J45: Category | K45: Budget | L45: Actual | M45: Difference
J46: Salary | K46: 0 | L46: {=SUMIF(D3:D28,$J46,E3:E28)} -> 0 | M46: {=L46-K46} -> 0
J47: Other/donations | K47: 0 | L47: {=SUMIF(D3:D28,$J47,E3:E28)} -> 0 | M47: {=L47+K47} -> 0
J48: Total | K48: {=SUM(K46:K47)} -> 0 | L48: {=SUM(L46:L47)} -> 0 | M48: {=L48-K$48} -> 0

Sheet September
B2: Date | C2: Description | D2: Category | E2: Amount
F30: Expenses Summary by Category
F31: Category | G31: Budget | H31: Actual | I31: Difference
F32: Restaurant | G32: 0 | H32: {=SUMIF(D3:D28,$F32,E3:E28)} -> 0 | I32: {=G32-H32} -> 0
F33: Sport & Activities | G33: 0 | H33: {=SUMIF(D3:D28,$F33,E3:E28)} -> 0 | I33: {=G33-H33} -> 0
F34: Food | G34: 0 | H34: {=SUMIF(D3:D28,$F34,E3:E28)} -> 0 | I34: {=G34-H34} -> 0
F35: Home | G35: 0 | H35: {=SUMIF(D3:D28,$F35,E3:E28)} -> 0 | I35: {=G35-H35} -> 0
F36: Medical | G36: 0 | H36: {=SUMIF(D3:D28,$F36,E3:E28)} -> 0 | I36: {=G36-H36} -> 0
F37: Personal Items | G37: 0 | H37: {=SUMIF(D3:D28,$F37,E3:E28)} -> 0 | I37: {=G37-H37} -> 0
F38: Travel & auto | G38: 0 | H38: {=SUMIF(D3:D28,$F38,E3:E28)} -> 0 | I38: {=G38-H38} -> 0
F39: Utilities & subscriptions | G39: 0 | H39: {=SUMIF(D3:D28,$F39,E3:E28)} -> 0 | I39: {=G39-H39} -> 0
F40: Other | G40: 0 | H40: {=SUMIF(D3:D28,$F40,E3:E28)} -> 0 | I40: {=G40-H40} -> 0
F41: Investment | H41: {=SUMIF(D3:D28,$F41,E3:E28)} -> 0 | I41: {=G41-H41} -> 0
F42: Total | G42: {=SUM(G32:G41)} -> 0 | H42: {=SUM(H32:H41)} -> 0 | I42: {=G42-H42} -> 0
J44: Income Summary
J45: Category | K45: Budget | L45: Actual | M45: Difference
J46: Salary | K46: 0 | L46: {=SUMIF(D3:D28,$J46,E3:E28)} -> 0 | M46: {=L46-K46} -> 0
J47: Other/donations | K47: 0 | L47: {=SUMIF(D3:D28,$J47,E3:E28)} -> 0 | M47: {=L47+K47} -> 0
J48: Total | K48: {=SUM(K46:K47)} -> 0 | L48: {=SUM(L46:L47)} -> 0 | M48: {=L48-K$48} -> 0
